[2024-01-15T11:38:29.836+0000] {taskinstance.py:1083} INFO - Dependencies all met for <TaskInstance: jumpit_jobinfo.s3_to_rds scheduled__2024-01-14T11:35:00+00:00 [queued]>
[2024-01-15T11:38:29.863+0000] {taskinstance.py:1083} INFO - Dependencies all met for <TaskInstance: jumpit_jobinfo.s3_to_rds scheduled__2024-01-14T11:35:00+00:00 [queued]>
[2024-01-15T11:38:29.864+0000] {taskinstance.py:1279} INFO - 
--------------------------------------------------------------------------------
[2024-01-15T11:38:29.864+0000] {taskinstance.py:1280} INFO - Starting attempt 2 of 2
[2024-01-15T11:38:29.864+0000] {taskinstance.py:1281} INFO - 
--------------------------------------------------------------------------------
[2024-01-15T11:38:29.913+0000] {taskinstance.py:1300} INFO - Executing <Task(PythonOperator): s3_to_rds> on 2024-01-14 11:35:00+00:00
[2024-01-15T11:38:29.936+0000] {standard_task_runner.py:55} INFO - Started process 34128 to run task
[2024-01-15T11:38:29.941+0000] {standard_task_runner.py:82} INFO - Running: ['***', 'tasks', 'run', 'jumpit_jobinfo', 's3_to_rds', 'scheduled__2024-01-14T11:35:00+00:00', '--job-id', '594', '--raw', '--subdir', 'DAGS_FOLDER/jobinfo_jumpit.py', '--cfg-path', '/tmp/tmpykshe15y']
[2024-01-15T11:38:29.949+0000] {standard_task_runner.py:83} INFO - Job 594: Subtask s3_to_rds
[2024-01-15T11:38:30.274+0000] {task_command.py:388} INFO - Running <TaskInstance: jumpit_jobinfo.s3_to_rds scheduled__2024-01-14T11:35:00+00:00 [running]> on host 565f6bcc10b6
[2024-01-15T11:38:30.489+0000] {taskinstance.py:1509} INFO - Exporting the following env vars:
AIRFLOW_CTX_DAG_OWNER=***
AIRFLOW_CTX_DAG_ID=jumpit_jobinfo
AIRFLOW_CTX_TASK_ID=s3_to_rds
AIRFLOW_CTX_EXECUTION_DATE=2024-01-14T11:35:00+00:00
AIRFLOW_CTX_TRY_NUMBER=2
AIRFLOW_CTX_DAG_RUN_ID=scheduled__2024-01-14T11:35:00+00:00
[2024-01-15T11:38:30.508+0000] {base.py:73} INFO - Using connection ID 's3_conn' for task execution.
[2024-01-15T11:38:30.727+0000] {taskinstance.py:1768} ERROR - Task failed with exception
Traceback (most recent call last):
  File "/home/airflow/.local/lib/python3.7/site-packages/airflow/operators/python.py", line 175, in execute
    return_value = self.execute_callable()
  File "/home/airflow/.local/lib/python3.7/site-packages/airflow/operators/python.py", line 192, in execute_callable
    return self.python_callable(*self.op_args, **self.op_kwargs)
  File "/opt/airflow/dags/jobinfo_jumpit.py", line 124, in s3_to_rds
    s3_object = s3_client.get_object(Bucket=s3_bucket, Key=s3_key)
  File "/home/airflow/.local/lib/python3.7/site-packages/botocore/client.py", line 530, in _api_call
    return self._make_api_call(operation_name, kwargs)
  File "/home/airflow/.local/lib/python3.7/site-packages/botocore/client.py", line 960, in _make_api_call
    raise error_class(parsed_response, operation_name)
botocore.errorfactory.NoSuchKey: An error occurred (NoSuchKey) when calling the GetObject operation: The specified key does not exist.
[2024-01-15T11:38:30.742+0000] {taskinstance.py:1323} INFO - Marking task as FAILED. dag_id=jumpit_jobinfo, task_id=s3_to_rds, execution_date=20240114T113500, start_date=20240115T113829, end_date=20240115T113830
[2024-01-15T11:38:30.763+0000] {standard_task_runner.py:105} ERROR - Failed to execute job 594 for task s3_to_rds (An error occurred (NoSuchKey) when calling the GetObject operation: The specified key does not exist.; 34128)
[2024-01-15T11:38:30.793+0000] {local_task_job.py:208} INFO - Task exited with return code 1
[2024-01-15T11:38:30.812+0000] {taskinstance.py:2578} INFO - 0 downstream tasks scheduled from follow-on schedule check
