[2024-01-13T11:23:35.961+0000] {taskinstance.py:1083} INFO - Dependencies all met for <TaskInstance: jobinfo_jobplanet.create_infomation_s3 manual__2024-01-13T11:23:27.334388+00:00 [queued]>
[2024-01-13T11:23:35.970+0000] {taskinstance.py:1083} INFO - Dependencies all met for <TaskInstance: jobinfo_jobplanet.create_infomation_s3 manual__2024-01-13T11:23:27.334388+00:00 [queued]>
[2024-01-13T11:23:35.970+0000] {taskinstance.py:1279} INFO - 
--------------------------------------------------------------------------------
[2024-01-13T11:23:35.971+0000] {taskinstance.py:1280} INFO - Starting attempt 1 of 1
[2024-01-13T11:23:35.971+0000] {taskinstance.py:1281} INFO - 
--------------------------------------------------------------------------------
[2024-01-13T11:23:35.986+0000] {taskinstance.py:1300} INFO - Executing <Task(PythonOperator): create_infomation_s3> on 2024-01-13 11:23:27.334388+00:00
[2024-01-13T11:23:35.992+0000] {standard_task_runner.py:55} INFO - Started process 4332 to run task
[2024-01-13T11:23:35.994+0000] {standard_task_runner.py:82} INFO - Running: ['***', 'tasks', 'run', 'jobinfo_jobplanet', 'create_infomation_s3', 'manual__2024-01-13T11:23:27.334388+00:00', '--job-id', '351', '--raw', '--subdir', 'DAGS_FOLDER/jobinfo_jobplanet.py', '--cfg-path', '/tmp/tmp1buzqenm']
[2024-01-13T11:23:35.994+0000] {standard_task_runner.py:83} INFO - Job 351: Subtask create_infomation_s3
[2024-01-13T11:23:36.223+0000] {task_command.py:388} INFO - Running <TaskInstance: jobinfo_jobplanet.create_infomation_s3 manual__2024-01-13T11:23:27.334388+00:00 [running]> on host 9d92fdf7265b
[2024-01-13T11:23:36.282+0000] {taskinstance.py:1509} INFO - Exporting the following env vars:
AIRFLOW_CTX_DAG_OWNER=***
AIRFLOW_CTX_DAG_ID=jobinfo_jobplanet
AIRFLOW_CTX_TASK_ID=create_infomation_s3
AIRFLOW_CTX_EXECUTION_DATE=2024-01-13T11:23:27.334388+00:00
AIRFLOW_CTX_TRY_NUMBER=1
AIRFLOW_CTX_DAG_RUN_ID=manual__2024-01-13T11:23:27.334388+00:00
[2024-01-13T11:23:36.283+0000] {jobinfo_jobplanet.py:48} INFO - 11111111111111111111111111111111
[2024-01-13T11:23:36.295+0000] {taskinstance.py:1768} ERROR - Task failed with exception
Traceback (most recent call last):
  File "/home/airflow/.local/lib/python3.7/site-packages/selenium/webdriver/common/selenium_manager.py", line 126, in run
    output = json.loads(stdout)
  File "/usr/local/lib/python3.7/json/__init__.py", line 348, in loads
    return _default_decoder.decode(s)
  File "/usr/local/lib/python3.7/json/decoder.py", line 337, in decode
    obj, end = self.raw_decode(s, idx=_w(s, 0).end())
  File "/usr/local/lib/python3.7/json/decoder.py", line 355, in raw_decode
    raise JSONDecodeError("Expecting value", s, err.value) from None
json.decoder.JSONDecodeError: Expecting value: line 1 column 1 (char 0)

The above exception was the direct cause of the following exception:

Traceback (most recent call last):
  File "/home/airflow/.local/lib/python3.7/site-packages/selenium/webdriver/common/driver_finder.py", line 38, in get_path
    path = SeleniumManager().driver_location(options) if path is None else path
  File "/home/airflow/.local/lib/python3.7/site-packages/selenium/webdriver/common/selenium_manager.py", line 90, in driver_location
    output = self.run(args)
  File "/home/airflow/.local/lib/python3.7/site-packages/selenium/webdriver/common/selenium_manager.py", line 129, in run
    raise WebDriverException(f"Unsuccessful command executed: {command}") from err
selenium.common.exceptions.WebDriverException: Message: Unsuccessful command executed: /home/airflow/.local/lib/python3.7/site-packages/selenium/webdriver/common/linux/selenium-manager --browser chrome --output json


The above exception was the direct cause of the following exception:

Traceback (most recent call last):
  File "/home/airflow/.local/lib/python3.7/site-packages/airflow/operators/python.py", line 175, in execute
    return_value = self.execute_callable()
  File "/home/airflow/.local/lib/python3.7/site-packages/airflow/operators/python.py", line 192, in execute_callable
    return self.python_callable(*self.op_args, **self.op_kwargs)
  File "/opt/airflow/dags/jobinfo_jobplanet.py", line 86, in create_infomation_s3
    driver = jobplanet_login()
  File "/opt/airflow/dags/jobinfo_jobplanet.py", line 54, in jobplanet_login
    driver = webdriver.Chrome(options=chrome_options)
  File "/home/airflow/.local/lib/python3.7/site-packages/selenium/webdriver/chrome/webdriver.py", line 50, in __init__
    keep_alive,
  File "/home/airflow/.local/lib/python3.7/site-packages/selenium/webdriver/chromium/webdriver.py", line 51, in __init__
    self.service.path = DriverFinder.get_path(self.service, options)
  File "/home/airflow/.local/lib/python3.7/site-packages/selenium/webdriver/common/driver_finder.py", line 41, in get_path
    raise NoSuchDriverException(msg) from err
selenium.common.exceptions.NoSuchDriverException: Message: Unable to obtain driver for chrome using Selenium Manager.; For documentation on this error, please visit: https://www.selenium.dev/documentation/webdriver/troubleshooting/errors/driver_location

[2024-01-13T11:23:36.304+0000] {taskinstance.py:1323} INFO - Marking task as FAILED. dag_id=jobinfo_jobplanet, task_id=create_infomation_s3, execution_date=20240113T112327, start_date=20240113T112335, end_date=20240113T112336
[2024-01-13T11:23:36.319+0000] {standard_task_runner.py:105} ERROR - Failed to execute job 351 for task create_infomation_s3 (Message: Unable to obtain driver for chrome using Selenium Manager.; For documentation on this error, please visit: https://www.selenium.dev/documentation/webdriver/troubleshooting/errors/driver_location
; 4332)
[2024-01-13T11:23:36.369+0000] {local_task_job.py:208} INFO - Task exited with return code 1
[2024-01-13T11:23:36.517+0000] {taskinstance.py:2578} INFO - 0 downstream tasks scheduled from follow-on schedule check
