[2024-01-15T11:47:41.045+0000] {taskinstance.py:1083} INFO - Dependencies all met for <TaskInstance: jobinfo_jobplanet.s3_to_rds scheduled__2024-01-14T11:46:00+00:00 [queued]>
[2024-01-15T11:47:41.066+0000] {taskinstance.py:1083} INFO - Dependencies all met for <TaskInstance: jobinfo_jobplanet.s3_to_rds scheduled__2024-01-14T11:46:00+00:00 [queued]>
[2024-01-15T11:47:41.067+0000] {taskinstance.py:1279} INFO - 
--------------------------------------------------------------------------------
[2024-01-15T11:47:41.067+0000] {taskinstance.py:1280} INFO - Starting attempt 1 of 1
[2024-01-15T11:47:41.067+0000] {taskinstance.py:1281} INFO - 
--------------------------------------------------------------------------------
[2024-01-15T11:47:41.332+0000] {taskinstance.py:1300} INFO - Executing <Task(PythonOperator): s3_to_rds> on 2024-01-14 11:46:00+00:00
[2024-01-15T11:47:41.347+0000] {standard_task_runner.py:55} INFO - Started process 34592 to run task
[2024-01-15T11:47:41.353+0000] {standard_task_runner.py:82} INFO - Running: ['***', 'tasks', 'run', 'jobinfo_jobplanet', 's3_to_rds', 'scheduled__2024-01-14T11:46:00+00:00', '--job-id', '603', '--raw', '--subdir', 'DAGS_FOLDER/jobinfo_jobplanet.py', '--cfg-path', '/tmp/tmppyno5qir']
[2024-01-15T11:47:41.354+0000] {standard_task_runner.py:83} INFO - Job 603: Subtask s3_to_rds
[2024-01-15T11:47:41.431+0000] {task_command.py:388} INFO - Running <TaskInstance: jobinfo_jobplanet.s3_to_rds scheduled__2024-01-14T11:46:00+00:00 [running]> on host 565f6bcc10b6
[2024-01-15T11:47:41.515+0000] {taskinstance.py:1509} INFO - Exporting the following env vars:
AIRFLOW_CTX_DAG_OWNER=***
AIRFLOW_CTX_DAG_ID=jobinfo_jobplanet
AIRFLOW_CTX_TASK_ID=s3_to_rds
AIRFLOW_CTX_EXECUTION_DATE=2024-01-14T11:46:00+00:00
AIRFLOW_CTX_TRY_NUMBER=1
AIRFLOW_CTX_DAG_RUN_ID=scheduled__2024-01-14T11:46:00+00:00
[2024-01-15T11:47:41.784+0000] {base.py:73} INFO - Using connection ID 'rds_conn' for task execution.
[2024-01-15T11:47:42.065+0000] {taskinstance.py:1768} ERROR - Task failed with exception
Traceback (most recent call last):
  File "/home/airflow/.local/lib/python3.7/site-packages/airflow/operators/python.py", line 175, in execute
    return_value = self.execute_callable()
  File "/home/airflow/.local/lib/python3.7/site-packages/airflow/operators/python.py", line 192, in execute_callable
    return self.python_callable(*self.op_args, **self.op_kwargs)
  File "/opt/airflow/dags/jobinfo_jobplanet.py", line 720, in s3_to_rds
    cur.execute(insert_query, tuple(row))
  File "/home/airflow/.local/lib/python3.7/site-packages/MySQLdb/cursors.py", line 199, in execute
    args = tuple(map(db.literal, args))
  File "/home/airflow/.local/lib/python3.7/site-packages/MySQLdb/connections.py", line 283, in literal
    s = self.escape(o, self.encoders)
  File "/home/airflow/.local/lib/python3.7/site-packages/MySQLdb/converters.py", line 76, in Float2Str
    raise ProgrammingError("%s can not be used with MySQL" % s)
MySQLdb.ProgrammingError: nan can not be used with MySQL
[2024-01-15T11:47:42.072+0000] {taskinstance.py:1323} INFO - Marking task as FAILED. dag_id=jobinfo_jobplanet, task_id=s3_to_rds, execution_date=20240114T114600, start_date=20240115T114741, end_date=20240115T114742
[2024-01-15T11:47:42.091+0000] {standard_task_runner.py:105} ERROR - Failed to execute job 603 for task s3_to_rds (nan can not be used with MySQL; 34592)
[2024-01-15T11:47:42.125+0000] {local_task_job.py:208} INFO - Task exited with return code 1
[2024-01-15T11:47:42.155+0000] {taskinstance.py:2578} INFO - 0 downstream tasks scheduled from follow-on schedule check
